2020-02-13 12:28:09,109 django.request ERROR    Internal Server Error: /user/login/
Traceback (most recent call last):
  File "/Library/Frameworks/Python.framework/Versions/3.7/lib/python3.7/site-packages/django/core/handlers/exception.py", line 35, in inner
    response = get_response(request)
  File "/Library/Frameworks/Python.framework/Versions/3.7/lib/python3.7/site-packages/django/core/handlers/base.py", line 128, in _get_response
    response = self.process_exception_by_middleware(e, request)
  File "/Library/Frameworks/Python.framework/Versions/3.7/lib/python3.7/site-packages/django/core/handlers/base.py", line 126, in _get_response
    response = wrapped_callback(request, *callback_args, **callback_kwargs)
  File "/Library/Frameworks/Python.framework/Versions/3.7/lib/python3.7/site-packages/ratelimit/decorators.py", line 30, in _wrapped
    return fn(*args, **kw)
  File "/Library/Frameworks/Python.framework/Versions/3.7/lib/python3.7/site-packages/django/views/decorators/csrf.py", line 54, in wrapped_view
    return view_func(*args, **kwargs)
  File "/Library/Frameworks/Python.framework/Versions/3.7/lib/python3.7/site-packages/django/views/decorators/csrf.py", line 54, in wrapped_view
    return view_func(*args, **kwargs)
  File "/Library/Frameworks/Python.framework/Versions/3.7/lib/python3.7/site-packages/django/views/generic/base.py", line 69, in view
    return self.dispatch(request, *args, **kwargs)
  File "/Library/Frameworks/Python.framework/Versions/3.7/lib/python3.7/site-packages/rest_framework/views.py", line 505, in dispatch
    response = self.handle_exception(exc)
  File "/Library/Frameworks/Python.framework/Versions/3.7/lib/python3.7/site-packages/rest_framework/views.py", line 465, in handle_exception
    self.raise_uncaught_exception(exc)
  File "/Library/Frameworks/Python.framework/Versions/3.7/lib/python3.7/site-packages/rest_framework/views.py", line 476, in raise_uncaught_exception
    raise exc
  File "/Library/Frameworks/Python.framework/Versions/3.7/lib/python3.7/site-packages/rest_framework/views.py", line 502, in dispatch
    response = handler(request, *args, **kwargs)
  File "/Library/Frameworks/Python.framework/Versions/3.7/lib/python3.7/site-packages/rest_framework/decorators.py", line 50, in handler
    return func(*args, **kwargs)
  File "/Users/shravani/Documents/Advanced Software Engg/Latest/yaatra-services/user/views.py", line 30, in user_login
    machine_ip = socket.gethostbyname(host_name)
socket.gaierror: [Errno 8] nodename nor servname provided, or not known
2020-02-13 12:36:06,796 django.request ERROR    Internal Server Error: /user/login/
Traceback (most recent call last):
  File "/Library/Frameworks/Python.framework/Versions/3.7/lib/python3.7/site-packages/django/core/handlers/exception.py", line 35, in inner
    response = get_response(request)
  File "/Library/Frameworks/Python.framework/Versions/3.7/lib/python3.7/site-packages/django/core/handlers/base.py", line 128, in _get_response
    response = self.process_exception_by_middleware(e, request)
  File "/Library/Frameworks/Python.framework/Versions/3.7/lib/python3.7/site-packages/django/core/handlers/base.py", line 126, in _get_response
    response = wrapped_callback(request, *callback_args, **callback_kwargs)
  File "/Library/Frameworks/Python.framework/Versions/3.7/lib/python3.7/site-packages/ratelimit/decorators.py", line 30, in _wrapped
    return fn(*args, **kw)
  File "/Library/Frameworks/Python.framework/Versions/3.7/lib/python3.7/site-packages/django/views/decorators/csrf.py", line 54, in wrapped_view
    return view_func(*args, **kwargs)
  File "/Library/Frameworks/Python.framework/Versions/3.7/lib/python3.7/site-packages/django/views/decorators/csrf.py", line 54, in wrapped_view
    return view_func(*args, **kwargs)
  File "/Library/Frameworks/Python.framework/Versions/3.7/lib/python3.7/site-packages/django/views/generic/base.py", line 69, in view
    return self.dispatch(request, *args, **kwargs)
  File "/Library/Frameworks/Python.framework/Versions/3.7/lib/python3.7/site-packages/rest_framework/views.py", line 505, in dispatch
    response = self.handle_exception(exc)
  File "/Library/Frameworks/Python.framework/Versions/3.7/lib/python3.7/site-packages/rest_framework/views.py", line 465, in handle_exception
    self.raise_uncaught_exception(exc)
  File "/Library/Frameworks/Python.framework/Versions/3.7/lib/python3.7/site-packages/rest_framework/views.py", line 476, in raise_uncaught_exception
    raise exc
  File "/Library/Frameworks/Python.framework/Versions/3.7/lib/python3.7/site-packages/rest_framework/views.py", line 502, in dispatch
    response = handler(request, *args, **kwargs)
  File "/Library/Frameworks/Python.framework/Versions/3.7/lib/python3.7/site-packages/rest_framework/decorators.py", line 50, in handler
    return func(*args, **kwargs)
  File "/Users/shravani/Documents/Advanced Software Engg/Latest/yaatra-services/user/views.py", line 30, in user_login
    machine_ip = socket.gethostbyname(host_name)
socket.gaierror: [Errno 8] nodename nor servname provided, or not known
2020-02-13 12:46:09,244 django.request ERROR    Internal Server Error: /user/login/
Traceback (most recent call last):
  File "/Library/Frameworks/Python.framework/Versions/3.7/lib/python3.7/site-packages/django/core/handlers/exception.py", line 35, in inner
    response = get_response(request)
  File "/Library/Frameworks/Python.framework/Versions/3.7/lib/python3.7/site-packages/django/core/handlers/base.py", line 128, in _get_response
    response = self.process_exception_by_middleware(e, request)
  File "/Library/Frameworks/Python.framework/Versions/3.7/lib/python3.7/site-packages/django/core/handlers/base.py", line 126, in _get_response
    response = wrapped_callback(request, *callback_args, **callback_kwargs)
  File "/Library/Frameworks/Python.framework/Versions/3.7/lib/python3.7/site-packages/ratelimit/decorators.py", line 30, in _wrapped
    return fn(*args, **kw)
  File "/Library/Frameworks/Python.framework/Versions/3.7/lib/python3.7/site-packages/django/views/decorators/csrf.py", line 54, in wrapped_view
    return view_func(*args, **kwargs)
  File "/Library/Frameworks/Python.framework/Versions/3.7/lib/python3.7/site-packages/django/views/decorators/csrf.py", line 54, in wrapped_view
    return view_func(*args, **kwargs)
  File "/Library/Frameworks/Python.framework/Versions/3.7/lib/python3.7/site-packages/django/views/generic/base.py", line 69, in view
    return self.dispatch(request, *args, **kwargs)
  File "/Library/Frameworks/Python.framework/Versions/3.7/lib/python3.7/site-packages/rest_framework/views.py", line 505, in dispatch
    response = self.handle_exception(exc)
  File "/Library/Frameworks/Python.framework/Versions/3.7/lib/python3.7/site-packages/rest_framework/views.py", line 465, in handle_exception
    self.raise_uncaught_exception(exc)
  File "/Library/Frameworks/Python.framework/Versions/3.7/lib/python3.7/site-packages/rest_framework/views.py", line 476, in raise_uncaught_exception
    raise exc
  File "/Library/Frameworks/Python.framework/Versions/3.7/lib/python3.7/site-packages/rest_framework/views.py", line 502, in dispatch
    response = handler(request, *args, **kwargs)
  File "/Library/Frameworks/Python.framework/Versions/3.7/lib/python3.7/site-packages/rest_framework/decorators.py", line 50, in handler
    return func(*args, **kwargs)
  File "/Users/shravani/Documents/Advanced Software Engg/Latest/yaatra-services/user/views.py", line 31, in user_login
    logger = logging.getLogger(_name_)
NameError: name '_name_' is not defined
2020-02-13 12:48:31,303 root         INFO     Request is being served by Instance: Shravanis-MacBook-Air.local at IP: 127.0.0.1
2020-02-13 12:50:10,644 root         INFO     Request is being served by Instance: Shravanis-MacBook-Air.local at IP: 127.0.0.1
2020-02-13 12:50:49,557 django.request WARNING  Not Found: /commute/daily/1/
2020-02-13 12:50:59,480 django.request WARNING  Not Found: /commute/daily/123/
2020-02-13 13:26:23,002 django.request WARNING  Not Found: /commute/daily/123/
2020-02-13 13:26:24,385 django.request WARNING  Not Found: /commute/daily/123/
2020-02-13 13:26:27,660 django.request WARNING  Not Found: /commute/daily/123/
2020-02-13 13:26:59,878 django.request WARNING  Not Found: /commute/daily/
2020-02-13 13:27:35,441 root         INFO     Request is being served by Instance: Shravanis-MacBook-Air.local at IP: 127.0.0.1
2020-02-13 13:27:44,524 django.request WARNING  Not Found: /commute/daily/
2020-02-13 13:27:59,473 django.request WARNING  Not Found: /commute/daily/1
2020-02-13 15:01:58,274 root         INFO     Request is being served by Instance: Shravanis-MacBook-Air.local at IP: 127.0.0.1
2020-02-13 15:02:03,812 django.request WARNING  Not Found: /commute/daily/1
2020-02-13 15:02:45,800 django.request ERROR    Internal Server Error: /user/register/
Traceback (most recent call last):
  File "/Library/Frameworks/Python.framework/Versions/3.7/lib/python3.7/site-packages/django/db/backends/utils.py", line 85, in _execute
    return self.cursor.execute(sql, params)
psycopg2.errors.NotNullViolation: null value in column "pref_gender" violates not-null constraint
DETAIL:  Failing row contains (4, pbkdf2_sha256$100000$3RztW6XZ4pVc$QklR4AHdvIb5uKuJ2BR89dIThbrs3X..., test, test, test3, test3@tes1t.com, 2, m, 2020-02-13 15:02:45.795815+00, 2020-02-13 15:02:45.795846+00, f, t, f, f, null, null).


The above exception was the direct cause of the following exception:

Traceback (most recent call last):
  File "/Library/Frameworks/Python.framework/Versions/3.7/lib/python3.7/site-packages/django/core/handlers/exception.py", line 35, in inner
    response = get_response(request)
  File "/Library/Frameworks/Python.framework/Versions/3.7/lib/python3.7/site-packages/django/core/handlers/base.py", line 128, in _get_response
    response = self.process_exception_by_middleware(e, request)
  File "/Library/Frameworks/Python.framework/Versions/3.7/lib/python3.7/site-packages/django/core/handlers/base.py", line 126, in _get_response
    response = wrapped_callback(request, *callback_args, **callback_kwargs)
  File "/Library/Frameworks/Python.framework/Versions/3.7/lib/python3.7/site-packages/ratelimit/decorators.py", line 30, in _wrapped
    return fn(*args, **kw)
  File "/Library/Frameworks/Python.framework/Versions/3.7/lib/python3.7/site-packages/django/views/decorators/csrf.py", line 54, in wrapped_view
    return view_func(*args, **kwargs)
  File "/Library/Frameworks/Python.framework/Versions/3.7/lib/python3.7/site-packages/django/views/decorators/csrf.py", line 54, in wrapped_view
    return view_func(*args, **kwargs)
  File "/Library/Frameworks/Python.framework/Versions/3.7/lib/python3.7/site-packages/django/views/generic/base.py", line 69, in view
    return self.dispatch(request, *args, **kwargs)
  File "/Library/Frameworks/Python.framework/Versions/3.7/lib/python3.7/site-packages/rest_framework/views.py", line 505, in dispatch
    response = self.handle_exception(exc)
  File "/Library/Frameworks/Python.framework/Versions/3.7/lib/python3.7/site-packages/rest_framework/views.py", line 465, in handle_exception
    self.raise_uncaught_exception(exc)
  File "/Library/Frameworks/Python.framework/Versions/3.7/lib/python3.7/site-packages/rest_framework/views.py", line 476, in raise_uncaught_exception
    raise exc
  File "/Library/Frameworks/Python.framework/Versions/3.7/lib/python3.7/site-packages/rest_framework/views.py", line 502, in dispatch
    response = handler(request, *args, **kwargs)
  File "/Library/Frameworks/Python.framework/Versions/3.7/lib/python3.7/site-packages/rest_framework/decorators.py", line 50, in handler
    return func(*args, **kwargs)
  File "/Users/shravani/Documents/Advanced Software Engg/Latest/yaatra-services/user/views.py", line 100, in user_registration
    userDetails = serializer.save()
  File "/Users/shravani/Documents/Advanced Software Engg/Latest/yaatra-services/user/serializers.py", line 25, in save
    userDetails.save()
  File "/Library/Frameworks/Python.framework/Versions/3.7/lib/python3.7/site-packages/django/contrib/auth/base_user.py", line 73, in save
    super().save(*args, **kwargs)
  File "/Library/Frameworks/Python.framework/Versions/3.7/lib/python3.7/site-packages/django/db/models/base.py", line 729, in save
    force_update=force_update, update_fields=update_fields)
  File "/Library/Frameworks/Python.framework/Versions/3.7/lib/python3.7/site-packages/django/db/models/base.py", line 759, in save_base
    updated = self._save_table(raw, cls, force_insert, force_update, using, update_fields)
  File "/Library/Frameworks/Python.framework/Versions/3.7/lib/python3.7/site-packages/django/db/models/base.py", line 842, in _save_table
    result = self._do_insert(cls._base_manager, using, fields, update_pk, raw)
  File "/Library/Frameworks/Python.framework/Versions/3.7/lib/python3.7/site-packages/django/db/models/base.py", line 880, in _do_insert
    using=using, raw=raw)
  File "/Library/Frameworks/Python.framework/Versions/3.7/lib/python3.7/site-packages/django/db/models/manager.py", line 82, in manager_method
    return getattr(self.get_queryset(), name)(*args, **kwargs)
  File "/Library/Frameworks/Python.framework/Versions/3.7/lib/python3.7/site-packages/django/db/models/query.py", line 1128, in _insert
    return query.get_compiler(using=using).execute_sql(return_id)
  File "/Library/Frameworks/Python.framework/Versions/3.7/lib/python3.7/site-packages/django/db/models/sql/compiler.py", line 1285, in execute_sql
    cursor.execute(sql, params)
  File "/Library/Frameworks/Python.framework/Versions/3.7/lib/python3.7/site-packages/django/db/backends/utils.py", line 100, in execute
    return super().execute(sql, params)
  File "/Library/Frameworks/Python.framework/Versions/3.7/lib/python3.7/site-packages/django/db/backends/utils.py", line 68, in execute
    return self._execute_with_wrappers(sql, params, many=False, executor=self._execute)
  File "/Library/Frameworks/Python.framework/Versions/3.7/lib/python3.7/site-packages/django/db/backends/utils.py", line 77, in _execute_with_wrappers
    return executor(sql, params, many, context)
  File "/Library/Frameworks/Python.framework/Versions/3.7/lib/python3.7/site-packages/django/db/backends/utils.py", line 85, in _execute
    return self.cursor.execute(sql, params)
  File "/Library/Frameworks/Python.framework/Versions/3.7/lib/python3.7/site-packages/django/db/utils.py", line 89, in __exit__
    raise dj_exc_value.with_traceback(traceback) from exc_value
  File "/Library/Frameworks/Python.framework/Versions/3.7/lib/python3.7/site-packages/django/db/backends/utils.py", line 85, in _execute
    return self.cursor.execute(sql, params)
django.db.utils.IntegrityError: null value in column "pref_gender" violates not-null constraint
DETAIL:  Failing row contains (4, pbkdf2_sha256$100000$3RztW6XZ4pVc$QklR4AHdvIb5uKuJ2BR89dIThbrs3X..., test, test, test3, test3@tes1t.com, 2, m, 2020-02-13 15:02:45.795815+00, 2020-02-13 15:02:45.795846+00, f, t, f, f, null, null).

2020-02-13 15:05:54,810 root         INFO     Request is being served by Instance: Shravanis-MacBook-Air.local at IP: 127.0.0.1
2020-02-13 15:06:15,274 root         INFO     Request is being served by Instance: Shravanis-MacBook-Air.local at IP: 127.0.0.1
